Traceback (most recent call last):
  File "/usr/share/miniconda/lib/python3.9/site-packages/jupyter_cache/executors/utils.py", line 51, in single_nb_execution
    executenb(
  File "/usr/share/miniconda/lib/python3.9/site-packages/nbclient/client.py", line 1093, in execute
    return NotebookClient(nb=nb, resources=resources, km=km, **kwargs).execute()
  File "/usr/share/miniconda/lib/python3.9/site-packages/nbclient/util.py", line 84, in wrapped
    return just_run(coro(*args, **kwargs))
  File "/usr/share/miniconda/lib/python3.9/site-packages/nbclient/util.py", line 62, in just_run
    return loop.run_until_complete(coro)
  File "/usr/share/miniconda/lib/python3.9/asyncio/base_events.py", line 642, in run_until_complete
    return future.result()
  File "/usr/share/miniconda/lib/python3.9/site-packages/nbclient/client.py", line 559, in async_execute
    await self.async_execute_cell(
  File "/usr/share/miniconda/lib/python3.9/site-packages/nbclient/client.py", line 854, in async_execute_cell
    self._check_raise_for_error(cell, exec_reply)
  File "/usr/share/miniconda/lib/python3.9/site-packages/nbclient/client.py", line 756, in _check_raise_for_error
    raise CellExecutionError.from_cell_and_msg(cell, exec_reply_content)
nbclient.exceptions.CellExecutionError: An error occurred while executing the following cell:
------------------
from utils.loader_all import Record
from utils.torch_loader_all import Loader
from tools.split import PathSet
from tools.file import mkdir
------------------

[0;31m---------------------------------------------------------------------------[0m
[0;31mModuleNotFoundError[0m                       Traceback (most recent call last)
[0;32m/tmp/ipykernel_2746/2916477220.py[0m in [0;36m<module>[0;34m[0m
[1;32m      1[0m [0;32mfrom[0m [0mutils[0m[0;34m.[0m[0mloader_all[0m [0;32mimport[0m [0mRecord[0m[0;34m[0m[0;34m[0m[0m
[0;32m----> 2[0;31m [0;32mfrom[0m [0mutils[0m[0;34m.[0m[0mtorch_loader_all[0m [0;32mimport[0m [0mLoader[0m[0;34m[0m[0;34m[0m[0m
[0m[1;32m      3[0m [0;32mfrom[0m [0mtools[0m[0;34m.[0m[0msplit[0m [0;32mimport[0m [0mPathSet[0m[0;34m[0m[0;34m[0m[0m
[1;32m      4[0m [0;32mfrom[0m [0mtools[0m[0;34m.[0m[0mfile[0m [0;32mimport[0m [0mmkdir[0m[0;34m[0m[0;34m[0m[0m

[0;32m~/work/pytorch-book/pytorch-book/apps/utils/torch_loader_all.py[0m in [0;36m<module>[0;34m[0m
[1;32m      1[0m [0;32mfrom[0m [0mPIL[0m [0;32mimport[0m [0mImage[0m[0;34m[0m[0;34m[0m[0m
[0;32m----> 2[0;31m [0;32mfrom[0m [0mtorch[0m[0;34m.[0m[0mutils[0m[0;34m.[0m[0mdata[0m [0;32mimport[0m [0mDataLoader[0m[0;34m,[0m [0mDataset[0m[0;34m[0m[0;34m[0m[0m
[0m[1;32m      3[0m [0;32mfrom[0m [0mtorchvision[0m [0;32mimport[0m [0mtransforms[0m[0;34m[0m[0;34m[0m[0m
[1;32m      4[0m [0;34m[0m[0m
[1;32m      5[0m [0;32mfrom[0m [0mutils[0m[0;34m.[0m[0mloader_all[0m [0;32mimport[0m [0mRecord[0m[0;34m[0m[0;34m[0m[0m

[0;31mModuleNotFoundError[0m: No module named 'torch'
ModuleNotFoundError: No module named 'torch'

