Traceback (most recent call last):
  File "/usr/share/miniconda/lib/python3.9/site-packages/jupyter_cache/executors/utils.py", line 51, in single_nb_execution
    executenb(
  File "/usr/share/miniconda/lib/python3.9/site-packages/nbclient/client.py", line 1093, in execute
    return NotebookClient(nb=nb, resources=resources, km=km, **kwargs).execute()
  File "/usr/share/miniconda/lib/python3.9/site-packages/nbclient/util.py", line 84, in wrapped
    return just_run(coro(*args, **kwargs))
  File "/usr/share/miniconda/lib/python3.9/site-packages/nbclient/util.py", line 62, in just_run
    return loop.run_until_complete(coro)
  File "/usr/share/miniconda/lib/python3.9/asyncio/base_events.py", line 642, in run_until_complete
    return future.result()
  File "/usr/share/miniconda/lib/python3.9/site-packages/nbclient/client.py", line 559, in async_execute
    await self.async_execute_cell(
  File "/usr/share/miniconda/lib/python3.9/site-packages/nbclient/client.py", line 854, in async_execute_cell
    self._check_raise_for_error(cell, exec_reply)
  File "/usr/share/miniconda/lib/python3.9/site-packages/nbclient/client.py", line 756, in _check_raise_for_error
    raise CellExecutionError.from_cell_and_msg(cell, exec_reply_content)
nbclient.exceptions.CellExecutionError: An error occurred while executing the following cell:
------------------
def print_zip_dataset(zip_root):
    '''ÊâìÂç∞ÂéãÁº©Êñá‰ª∂ÁöÑÂêçÁß∞'''
    for zip_dir in Path(zip_root).iterdir():
        print(zip_dir.name)

print_zip_dataset(zip_root)
------------------

[0;31m---------------------------------------------------------------------------[0m
[0;31mFileNotFoundError[0m                         Traceback (most recent call last)
[0;32m/tmp/ipykernel_3023/291183120.py[0m in [0;36m<module>[0;34m[0m
[1;32m      4[0m         [0mprint[0m[0;34m([0m[0mzip_dir[0m[0;34m.[0m[0mname[0m[0;34m)[0m[0;34m[0m[0;34m[0m[0m
[1;32m      5[0m [0;34m[0m[0m
[0;32m----> 6[0;31m [0mprint_zip_dataset[0m[0;34m([0m[0mzip_root[0m[0;34m)[0m[0;34m[0m[0;34m[0m[0m
[0m
[0;32m/tmp/ipykernel_3023/291183120.py[0m in [0;36mprint_zip_dataset[0;34m(zip_root)[0m
[1;32m      1[0m [0;32mdef[0m [0mprint_zip_dataset[0m[0;34m([0m[0mzip_root[0m[0;34m)[0m[0;34m:[0m[0;34m[0m[0;34m[0m[0m
[1;32m      2[0m     [0;34m'''ÊâìÂç∞ÂéãÁº©Êñá‰ª∂ÁöÑÂêçÁß∞'''[0m[0;34m[0m[0;34m[0m[0m
[0;32m----> 3[0;31m     [0;32mfor[0m [0mzip_dir[0m [0;32min[0m [0mPath[0m[0;34m([0m[0mzip_root[0m[0;34m)[0m[0;34m.[0m[0miterdir[0m[0;34m([0m[0;34m)[0m[0;34m:[0m[0;34m[0m[0;34m[0m[0m
[0m[1;32m      4[0m         [0mprint[0m[0;34m([0m[0mzip_dir[0m[0;34m.[0m[0mname[0m[0;34m)[0m[0;34m[0m[0;34m[0m[0m
[1;32m      5[0m [0;34m[0m[0m

[0;32m/usr/share/miniconda/lib/python3.9/pathlib.py[0m in [0;36miterdir[0;34m(self)[0m
[1;32m   1148[0m         [0mresult[0m [0;32mfor[0m [0mthe[0m [0mspecial[0m [0mpaths[0m [0;34m'.'[0m [0;32mand[0m [0;34m'..'[0m[0;34m.[0m[0;34m[0m[0;34m[0m[0m
[1;32m   1149[0m         """
[0;32m-> 1150[0;31m         [0;32mfor[0m [0mname[0m [0;32min[0m [0mself[0m[0;34m.[0m[0m_accessor[0m[0;34m.[0m[0mlistdir[0m[0;34m([0m[0mself[0m[0;34m)[0m[0;34m:[0m[0;34m[0m[0;34m[0m[0m
[0m[1;32m   1151[0m             [0;32mif[0m [0mname[0m [0;32min[0m [0;34m{[0m[0;34m'.'[0m[0;34m,[0m [0;34m'..'[0m[0;34m}[0m[0;34m:[0m[0;34m[0m[0;34m[0m[0m
[1;32m   1152[0m                 [0;31m# Yielding a path object for these makes little sense[0m[0;34m[0m[0;34m[0m[0;34m[0m[0m

[0;31mFileNotFoundError[0m: [Errno 2] No such file or directory: 'E:\\kaggle\\gan\\zip'
FileNotFoundError: [Errno 2] No such file or directory: 'E:\\kaggle\\gan\\zip'

